Workbook

Sheet 1_Inventory
A1: INVENTORY MASTER (ฐานข้อมูลวัตถุดิบ)
A2: Material_ID | B2: Material_Name | C2: Purchase_Price | D2: Purchase_Qty | E2: Purchase_Unit | F2: Unit_Conversion_g_ml | G2: Cost_Per_Unit_Use
A3: M001 | B3: แป้งเค้ก (Cake Flour) | C3: 45 | D3: 1 | E3: kg | F3: 1000 | G3: =C3/(D3*F3) -> 0
A4: M002 | B4: น้ำตาลทราย (Sugar) | C4: 24 | D4: 1 | E4: kg | F4: 1000 | G4: =C4/(D4*F4) -> 0
A5: M003 | B5: เนยสด (Butter) | C5: 180 | D5: 1 | E5: kg | F5: 1000 | G5: =C5/(D5*F5) -> 0
A6: M004 | B6: ไข่ไก่ (Eggs) | C6: 120 | D6: 30 | E6: fong (pcs) | F6: 1 | G6: =C6/(D6*F6) -> 0
A7: M005 | B7: นมสด (Milk) | C7: 95 | D7: 2 | E7: L | F7: 1000 | G7: =C7/(D7*F7) -> 0
A8: M006 | B8: ผงโกโก้ (Cocoa Powder) | C8: 350 | D8: 1 | E8: kg | F8: 1000 | G8: =C8/(D8*F8) -> 0
A9: M007 | B9: กลิ่นวานิลลา (Vanilla) | C9: 450 | D9: 0.5 | E9: L | F9: 1000 | G9: =C9/(D9*F9) -> 0
A10: M008 | B10: สตรอว์เบอร์รีสด (Strawberry) | C10: 250 | D10: 1 | E10: kg | F10: 1000 | G10: =C10/(D10*F10) -> 0
A11: M009 | B11: วิปครีม (Whipping Cream) | C11: 160 | D11: 1 | E11: L | F11: 1000 | G11: =C11/(D11*F11) -> 0
A12: M010 | B12: แป้งขนมปัง (Bread Flour) | C12: 40 | D12: 1 | E12: kg | F12: 1000 | G12: =C12/(D12*F12) -> 0

Sheet 2_Recipe_Master
A1: MENU PRICE LIST (ตารางสรุปราคาขาย)
A2: Menu_ID | B2: Menu_Name | C2: Total_Cost | D2: Target_Margin% | E2: Rec_Price | F2: Final_Selling_Price
A3: MN01 | B3: Strawberry Shortcake | C3: =E23 -> 0 | D3: 0.6 | E3: =C3*(1+D3) -> 0 | F3: =E3 -> 0
A4: MN02 | B4: Double Choc Brownie | C4: =E38 -> 0 | D4: 0.5 | E4: =C4*(1+D4) -> 0 | F4: =E4 -> 0
A5: MN03 | B5: Oatmeal Raisin Cookie | C5: =E53 -> 0 | D5: 0.5 | E5: =C5*(1+D5) -> 0 | F5: =E5 -> 0
A6: MN04 | B6: Butter Croissant | C6: =E68 -> 0 | D6: 0.45 | E6: =C6*(1+D6) -> 0 | F6: =E6 -> 0
A7: MN05 | B7: Coconut Pie | C7: =E83 -> 0 | D7: 0.55 | E7: =C7*(1+D7) -> 0 | F7: =E7 -> 0
A13: RECIPE CARD: Strawberry Shortcake (MN01)
A14: Ingredient_Name | B14: Qty_Used (g) | C14: Cost/g (Link) | D14: Line_Cost
C15: =IFERROR(VLOOKUP(A14, '1_Inventory'!$B$2:$G$12, 6, FALSE), 0) -> 0 | D15: =B14*C14 -> 0
C16: =IFERROR(VLOOKUP(A15, '1_Inventory'!$B$2:$G$12, 6, FALSE), 0) -> 0 | D16: =B15*C15 -> 0
C17: =IFERROR(VLOOKUP(A16, '1_Inventory'!$B$2:$G$12, 6, FALSE), 0) -> 0 | D17: =B16*C16 -> 0
C18: =IFERROR(VLOOKUP(A17, '1_Inventory'!$B$2:$G$12, 6, FALSE), 0) -> 0 | D18: =B17*C17 -> 0
C19: =IFERROR(VLOOKUP(A18, '1_Inventory'!$B$2:$G$12, 6, FALSE), 0) -> 0 | D19: =B18*C18 -> 0
D20: Raw Cost | E20: =SUM(D14:D19) -> 0
D21: Loss (10%) | E21: =E20*0.1 -> 0
D22: TOTAL COST | E22: =E20+E21 -> 0
A28: RECIPE CARD: Double Choc Brownie (MN02)
A29: Ingredient_Name | B29: Qty_Used (g) | C29: Cost/g (Link) | D29: Line_Cost
C30: =IFERROR(VLOOKUP(A29, '1_Inventory'!$B$2:$G$12, 6, FALSE), 0) -> 0 | D30: =B29*C29 -> 0
C31: =IFERROR(VLOOKUP(A30, '1_Inventory'!$B$2:$G$12, 6, FALSE), 0) -> 0 | D31: =B30*C30 -> 0
C32: =IFERROR(VLOOKUP(A31, '1_Inventory'!$B$2:$G$12, 6, FALSE), 0) -> 0 | D32: =B31*C31 -> 0
C33: =IFERROR(VLOOKUP(A32, '1_Inventory'!$B$2:$G$12, 6, FALSE), 0) -> 0 | D33: =B32*C32 -> 0
C34: =IFERROR(VLOOKUP(A33, '1_Inventory'!$B$2:$G$12, 6, FALSE), 0) -> 0 | D34: =B33*C33 -> 0
D35: Raw Cost | E35: =SUM(D29:D34) -> 0
D36: Loss (10%) | E36: =E35*0.1 -> 0
D37: TOTAL COST | E37: =E35+E36 -> 0
A43: RECIPE CARD: Oatmeal Raisin Cookie (MN03)
A44: Ingredient_Name | B44: Qty_Used (g) | C44: Cost/g (Link) | D44: Line_Cost
C45: =IFERROR(VLOOKUP(A44, '1_Inventory'!$B$2:$G$12, 6, FALSE), 0) -> 0 | D45: =B44*C44 -> 0
C46: =IFERROR(VLOOKUP(A45, '1_Inventory'!$B$2:$G$12, 6, FALSE), 0) -> 0 | D46: =B45*C45 -> 0
C47: =IFERROR(VLOOKUP(A46, '1_Inventory'!$B$2:$G$12, 6, FALSE), 0) -> 0 | D47: =B46*C46 -> 0
C48: =IFERROR(VLOOKUP(A47, '1_Inventory'!$B$2:$G$12, 6, FALSE), 0) -> 0 | D48: =B47*C47 -> 0
C49: =IFERROR(VLOOKUP(A48, '1_Inventory'!$B$2:$G$12, 6, FALSE), 0) -> 0 | D49: =B48*C48 -> 0
D50: Raw Cost | E50: =SUM(D44:D49) -> 0
D51: Loss (10%) | E51: =E50*0.1 -> 0
D52: TOTAL COST | E52: =E50+E51 -> 0
A58: RECIPE CARD: Butter Croissant (MN04)
A59: Ingredient_Name | B59: Qty_Used (g) | C59: Cost/g (Link) | D59: Line_Cost
C60: =IFERROR(VLOOKUP(A59, '1_Inventory'!$B$2:$G$12, 6, FALSE), 0) -> 0 | D60: =B59*C59 -> 0
...

Sheet 3_Daily_Sales
A1: DAILY SALES LOG
A2: Date | B2: Menu_Item | C2: Qty_Sold | D2: Unit_Price | E2: Unit_Cost | F2: Total_Sales | G2: Total_Cost | H2: Gross_Profit
D3: =IFERROR(VLOOKUP(B3, '2_Recipe_Master'!$B$2:$F$6, 5, FALSE), 0) -> 0 | E3: =IFERROR(VLOOKUP(B3, '2_Recipe_Master'!$B$2:$F$6, 2, FALSE), 0) -> 0 | F3: =C3*D3 -> 0 | G3: =C3*E3 -> 0 | H3: =F3-G3 -> 0
D4: =IFERROR(VLOOKUP(B4, '2_Recipe_Master'!$B$2:$F$6, 5, FALSE), 0) -> 0 | E4: =IFERROR(VLOOKUP(B4, '2_Recipe_Master'!$B$2:$F$6, 2, FALSE), 0) -> 0 | F4: =C4*D4 -> 0 | G4: =C4*E4 -> 0 | H4: =F4-G4 -> 0
D5: =IFERROR(VLOOKUP(B5, '2_Recipe_Master'!$B$2:$F$6, 5, FALSE), 0) -> 0 | E5: =IFERROR(VLOOKUP(B5, '2_Recipe_Master'!$B$2:$F$6, 2, FALSE), 0) -> 0 | F5: =C5*D5 -> 0 | G5: =C5*E5 -> 0 | H5: =F5-G5 -> 0
D6: =IFERROR(VLOOKUP(B6, '2_Recipe_Master'!$B$2:$F$6, 5, FALSE), 0) -> 0 | E6: =IFERROR(VLOOKUP(B6, '2_Recipe_Master'!$B$2:$F$6, 2, FALSE), 0) -> 0 | F6: =C6*D6 -> 0 | G6: =C6*E6 -> 0 | H6: =F6-G6 -> 0
D7: =IFERROR(VLOOKUP(B7, '2_Recipe_Master'!$B$2:$F$6, 5, FALSE), 0) -> 0 | E7: =IFERROR(VLOOKUP(B7, '2_Recipe_Master'!$B$2:$F$6, 2, FALSE), 0) -> 0 | F7: =C7*D7 -> 0 | G7: =C7*E7 -> 0 | H7: =F7-G7 -> 0
D8: =IFERROR(VLOOKUP(B8, '2_Recipe_Master'!$B$2:$F$6, 5, FALSE), 0) -> 0 | E8: =IFERROR(VLOOKUP(B8, '2_Recipe_Master'!$B$2:$F$6, 2, FALSE), 0) -> 0 | F8: =C8*D8 -> 0 | G8: =C8*E8 -> 0 | H8: =F8-G8 -> 0
D9: =IFERROR(VLOOKUP(B9, '2_Recipe_Master'!$B$2:$F$6, 5, FALSE), 0) -> 0 | E9: =IFERROR(VLOOKUP(B9, '2_Recipe_Master'!$B$2:$F$6, 2, FALSE), 0) -> 0 | F9: =C9*D9 -> 0 | G9: =C9*E9 -> 0 | H9: =F9-G9 -> 0
D10: =IFERROR(VLOOKUP(B10, '2_Recipe_Master'!$B$2:$F$6, 5, FALSE), 0) -> 0 | E10: =IFERROR(VLOOKUP(B10, '2_Recipe_Master'!$B$2:$F$6, 2, FALSE), 0) -> 0 | F10: =C10*D10 -> 0 | G10: =C10*E10 -> 0 | H10: =F10-G10 -> 0
D11: =IFERROR(VLOOKUP(B11, '2_Recipe_Master'!$B$2:$F$6, 5, FALSE), 0) -> 0 | E11: =IFERROR(VLOOKUP(B11, '2_Recipe_Master'!$B$2:$F$6, 2, FALSE), 0) -> 0 | F11: =C11*D11 -> 0 | G11: =C11*E11 -> 0 | H11: =F11-G11 -> 0
D12: =IFERROR(VLOOKUP(B12, '2_Recipe_Master'!$B$2:$F$6, 5, FALSE), 0) -> 0 | E12: =IFERROR(VLOOKUP(B12, '2_Recipe_Master'!$B$2:$F$6, 2, FALSE), 0) -> 0 | F12: =C12*D12 -> 0 | G12: =C12*E12 -> 0 | H12: =F12-G12 -> 0

Sheet 4_Dashboard
A1: BUSINESS DASHBOARD
A3: Total Sales | B3: =SUM('3_Daily_Sales'!F:F) -> 0
A4: Total Profit | B4: =SUM('3_Daily_Sales'!H:H) -> 0
A5: Avg Margin % | B5: =IF(B3=0, 0, B4/B3) -> 0
