Workbook

Sheet 1_Inventory
A1: INVENTORY MASTER
A2: ID | B2: Material Name | C2: Purchase Price | D2: Qty | E2: Unit | F2: Grams per Unit | G2: Cost/Gram
A3: M001 | B3: แป้งเค้ก (Cake Flour) | C3: 45 | D3: 1 | E3: kg | F3: 1000 | G3: =C3/(D3*F3) -> 0
A4: M002 | B4: น้ำตาลทราย (Sugar) | C4: 24 | D4: 1 | E4: kg | F4: 1000 | G4: =C4/(D4*F4) -> 0
A5: M003 | B5: เนยสด (Butter) | C5: 180 | D5: 1 | E5: kg | F5: 1000 | G5: =C5/(D5*F5) -> 0
A6: M004 | B6: ไข่ไก่ (Eggs) | C6: 120 | D6: 30 | E6: pcs | F6: 55 | G6: =C6/(D6*F6) -> 0
A7: M005 | B7: นมสด (Milk) | C7: 95 | D7: 2 | E7: L | F7: 1000 | G7: =C7/(D7*F7) -> 0
A8: M006 | B8: ผงโกโก้ (Cocoa) | C8: 350 | D8: 1 | E8: kg | F8: 1000 | G8: =C8/(D8*F8) -> 0
A9: M007 | B9: สตรอว์เบอร์รี (Strawberry) | C9: 250 | D9: 1 | E9: kg | F9: 1000 | G9: =C9/(D9*F9) -> 0
A10: M008 | B10: วิปครีม (Whipping Cream) | C10: 160 | D10: 1 | E10: L | F10: 1000 | G10: =C10/(D10*F10) -> 0

Sheet 2_Recipe_Master
A1: MENU PRICING SUMMARY
A2: ID | B2: Menu Name | C2: Total Cost | D2: Target Margin % | E2: Rec. Price | F2: Final Price
A3: MN01 | B3: Strawberry Shortcake | C3: =E22 -> 0 | D3: 0.6 | E3: =C3/(1-D3) -> 0 | F3: =E3 -> 0
A4: MN02 | B4: Double Choc Brownie | C4: =E36 -> 0 | D4: 0.55 | E4: =C4/(1-D4) -> 0 | F4: =E4 -> 0
A5: MN03 | B5: Oatmeal Cookie | C5: =E50 -> 0 | D5: 0.5 | E5: =C5/(1-D5) -> 0 | F5: =E5 -> 0
A6: MN04 | B6: Butter Croissant | C6: =E64 -> 0 | D6: 0.5 | E6: =C6/(1-D6) -> 0 | F6: =E6 -> 0
A7: MN05 | B7: Coconut Pie | C7: =E78 -> 0 | D7: 0.6 | E7: =C7/(1-D7) -> 0 | F7: =E7 -> 0
A13: RECIPE: Strawberry Shortcake (MN01)
A14: Ingredient | B14: Qty (g) | C14: Cost/g (Link) | D14: Line Cost | E14: Notes
B15: 0 | C15: =IFERROR(VLOOKUP(A15,'1_Inventory'!$B$3:$G$20,6,FALSE),0) -> 0 | D15: =B15*C15 -> 0
B16: 0 | C16: =IFERROR(VLOOKUP(A16,'1_Inventory'!$B$3:$G$20,6,FALSE),0) -> 0 | D16: =B16*C16 -> 0
B17: 0 | C17: =IFERROR(VLOOKUP(A17,'1_Inventory'!$B$3:$G$20,6,FALSE),0) -> 0 | D17: =B17*C17 -> 0
B18: 0 | C18: =IFERROR(VLOOKUP(A18,'1_Inventory'!$B$3:$G$20,6,FALSE),0) -> 0 | D18: =B18*C18 -> 0
B19: 0 | C19: =IFERROR(VLOOKUP(A19,'1_Inventory'!$B$3:$G$20,6,FALSE),0) -> 0 | D19: =B19*C19 -> 0
C20: Raw Material Cost | D20: =SUM(D15:D19) -> 0
C21: Loss % (Yield) | D21: 0.1
C22: TOTAL COST / PCS | D22: =D20/(1-D21) -> 0
A27: RECIPE: Double Choc Brownie (MN02)
A28: Ingredient | B28: Qty (g) | C28: Cost/g (Link) | D28: Line Cost | E28: Notes
B29: 0 | C29: =IFERROR(VLOOKUP(A29,'1_Inventory'!$B$3:$G$20,6,FALSE),0) -> 0 | D29: =B29*C29 -> 0
B30: 0 | C30: =IFERROR(VLOOKUP(A30,'1_Inventory'!$B$3:$G$20,6,FALSE),0) -> 0 | D30: =B30*C30 -> 0
B31: 0 | C31: =IFERROR(VLOOKUP(A31,'1_Inventory'!$B$3:$G$20,6,FALSE),0) -> 0 | D31: =B31*C31 -> 0
B32: 0 | C32: =IFERROR(VLOOKUP(A32,'1_Inventory'!$B$3:$G$20,6,FALSE),0) -> 0 | D32: =B32*C32 -> 0
B33: 0 | C33: =IFERROR(VLOOKUP(A33,'1_Inventory'!$B$3:$G$20,6,FALSE),0) -> 0 | D33: =B33*C33 -> 0
C34: Raw Material Cost | D34: =SUM(D29:D33) -> 0
C35: Loss % (Yield) | D35: 0.1
C36: TOTAL COST / PCS | D36: =D34/(1-D35) -> 0
A41: RECIPE: Oatmeal Cookie (MN03)
A42: Ingredient | B42: Qty (g) | C42: Cost/g (Link) | D42: Line Cost | E42: Notes
B43: 0 | C43: =IFERROR(VLOOKUP(A43,'1_Inventory'!$B$3:$G$20,6,FALSE),0) -> 0 | D43: =B43*C43 -> 0
B44: 0 | C44: =IFERROR(VLOOKUP(A44,'1_Inventory'!$B$3:$G$20,6,FALSE),0) -> 0 | D44: =B44*C44 -> 0
B45: 0 | C45: =IFERROR(VLOOKUP(A45,'1_Inventory'!$B$3:$G$20,6,FALSE),0) -> 0 | D45: =B45*C45 -> 0
B46: 0 | C46: =IFERROR(VLOOKUP(A46,'1_Inventory'!$B$3:$G$20,6,FALSE),0) -> 0 | D46: =B46*C46 -> 0
B47: 0 | C47: =IFERROR(VLOOKUP(A47,'1_Inventory'!$B$3:$G$20,6,FALSE),0) -> 0 | D47: =B47*C47 -> 0
C48: Raw Material Cost | D48: =SUM(D43:D47) -> 0
C49: Loss % (Yield) | D49: 0.1
C50: TOTAL COST / PCS | D50: =D48/(1-D49) -> 0
A55: RECIPE: Butter Croissant (MN04)
A56: Ingredient | B56: Qty (g) | C56: Cost/g (Link) | D56: Line Cost | E56: Notes
B57: 0 | C57: =IFERROR(VLOOKUP(A57,'1_Inventory'!$B$3:$G$20,6,FALSE),0) -> 0 | D57: =B57*C57 -> 0
...

Sheet 3_Daily_Sales
A1: DAILY SALES LOG
A2: Date | B2: Menu Item | C2: Qty Sold | D2: Selling Price | E2: Cost per Unit | F2: Total Sales | G2: Total Cost | H2: Gross Profit
D3: =IFERROR(VLOOKUP(B3,'2_Recipe_Master'!$B$3:$F$7,5,FALSE),0) -> 0 | E3: =IFERROR(VLOOKUP(B3,'2_Recipe_Master'!$B$3:$F$7,2,FALSE),0) -> 0 | F3: =C3*D3 -> 0 | G3: =C3*E3 -> 0 | H3: =F3-G3 -> 0
D4: =IFERROR(VLOOKUP(B4,'2_Recipe_Master'!$B$3:$F$7,5,FALSE),0) -> 0 | E4: =IFERROR(VLOOKUP(B4,'2_Recipe_Master'!$B$3:$F$7,2,FALSE),0) -> 0 | F4: =C4*D4 -> 0 | G4: =C4*E4 -> 0 | H4: =F4-G4 -> 0
D5: =IFERROR(VLOOKUP(B5,'2_Recipe_Master'!$B$3:$F$7,5,FALSE),0) -> 0 | E5: =IFERROR(VLOOKUP(B5,'2_Recipe_Master'!$B$3:$F$7,2,FALSE),0) -> 0 | F5: =C5*D5 -> 0 | G5: =C5*E5 -> 0 | H5: =F5-G5 -> 0
D6: =IFERROR(VLOOKUP(B6,'2_Recipe_Master'!$B$3:$F$7,5,FALSE),0) -> 0 | E6: =IFERROR(VLOOKUP(B6,'2_Recipe_Master'!$B$3:$F$7,2,FALSE),0) -> 0 | F6: =C6*D6 -> 0 | G6: =C6*E6 -> 0 | H6: =F6-G6 -> 0
D7: =IFERROR(VLOOKUP(B7,'2_Recipe_Master'!$B$3:$F$7,5,FALSE),0) -> 0 | E7: =IFERROR(VLOOKUP(B7,'2_Recipe_Master'!$B$3:$F$7,2,FALSE),0) -> 0 | F7: =C7*D7 -> 0 | G7: =C7*E7 -> 0 | H7: =F7-G7 -> 0
D8: =IFERROR(VLOOKUP(B8,'2_Recipe_Master'!$B$3:$F$7,5,FALSE),0) -> 0 | E8: =IFERROR(VLOOKUP(B8,'2_Recipe_Master'!$B$3:$F$7,2,FALSE),0) -> 0 | F8: =C8*D8 -> 0 | G8: =C8*E8 -> 0 | H8: =F8-G8 -> 0
D9: =IFERROR(VLOOKUP(B9,'2_Recipe_Master'!$B$3:$F$7,5,FALSE),0) -> 0 | E9: =IFERROR(VLOOKUP(B9,'2_Recipe_Master'!$B$3:$F$7,2,FALSE),0) -> 0 | F9: =C9*D9 -> 0 | G9: =C9*E9 -> 0 | H9: =F9-G9 -> 0
D10: =IFERROR(VLOOKUP(B10,'2_Recipe_Master'!$B$3:$F$7,5,FALSE),0) -> 0 | E10: =IFERROR(VLOOKUP(B10,'2_Recipe_Master'!$B$3:$F$7,2,FALSE),0) -> 0 | F10: =C10*D10 -> 0 | G10: =C10*E10 -> 0 | H10: =F10-G10 -> 0
D11: =IFERROR(VLOOKUP(B11,'2_Recipe_Master'!$B$3:$F$7,5,FALSE),0) -> 0 | E11: =IFERROR(VLOOKUP(B11,'2_Recipe_Master'!$B$3:$F$7,2,FALSE),0) -> 0 | F11: =C11*D11 -> 0 | G11: =C11*E11 -> 0 | H11: =F11-G11 -> 0
D12: =IFERROR(VLOOKUP(B12,'2_Recipe_Master'!$B$3:$F$7,5,FALSE),0) -> 0 | E12: =IFERROR(VLOOKUP(B12,'2_Recipe_Master'!$B$3:$F$7,2,FALSE),0) -> 0 | F12: =C12*D12 -> 0 | G12: =C12*E12 -> 0 | H12: =F12-G12 -> 0
D13: =IFERROR(VLOOKUP(B13,'2_Recipe_Master'!$B$3:$F$7,5,FALSE),0) -> 0 | E13: =IFERROR(VLOOKUP(B13,'2_Recipe_Master'!$B$3:$F$7,2,FALSE),0) -> 0 | F13: =C13*D13 -> 0 | G13: =C13*E13 -> 0 | H13: =F13-G13 -> 0
D14: =IFERROR(VLOOKUP(B14,'2_Recipe_Master'!$B$3:$F$7,5,FALSE),0) -> 0 | E14: =IFERROR(VLOOKUP(B14,'2_Recipe_Master'!$B$3:$F$7,2,FALSE),0) -> 0 | F14: =C14*D14 -> 0 | G14: =C14*E14 -> 0 | H14: =F14-G14 -> 0
... D22: =IFERROR(VLOOKUP(B22,'2_Recipe_Master'!$B$3:$F$7,5,FALSE),0) -> 0 | E22: =IFERROR(VLOOKUP(B22,'2_Recipe_Master'!$B$3:$F$7,2,FALSE),0) -> 0 | F22: =C22*D22 -> 0 | G22: =C22*E22 -> 0 | H22: =F22-G22 -> 0

Sheet 4_Dashboard
A1: BUSINESS SNAPSHOT
A3: Total Revenue | B3: =SUM('3_Daily_Sales'!F:F) -> 0
A4: Total Cost | B4: =SUM('3_Daily_Sales'!G:G) -> 0
A5: Net Profit | B5: =SUM('3_Daily_Sales'!H:H) -> 0
