Workbook

Sheet 1_Inventory
A1: INVENTORY MASTER
A2: ID | B2: Material Name | C2: Purchase Price | D2: Qty | E2: Unit | F2: G/Unit | G2: Cost/Gram
A3: M001 | B3: แป้งเค้ก | C3: 45 | D3: 1 | E3: kg | F3: 1000 | G3: =C3/(D3*F3) -> 0.045
A4: M002 | B4: น้ำตาลทราย | C4: 24 | D4: 1 | E4: kg | F4: 1000 | G4: =C4/(D4*F4) -> 0.024
A5: M003 | B5: เนยสด | C5: 180 | D5: 1 | E5: kg | F5: 1000 | G5: =C5/(D5*F5) -> 0.18
A6: M004 | B6: ไข่ไก่ | C6: 120 | D6: 30 | E6: pcs | F6: 55 | G6: =C6/(D6*F6) -> 0.072727273
A7: M005 | B7: นมสด | C7: 95 | D7: 2 | E7: L | F7: 1000 | G7: =C7/(D7*F7) -> 0.0475
A8: M006 | B8: สตรอว์เบอร์รี | C8: 250 | D8: 1 | E8: kg | F8: 1000 | G8: =C8/(D8*F8) -> 0.25

Sheet 2_Recipe_Master
A1: MENU PRICING
A2: ID | B2: Menu Name | C2: Total Cost | D2: Target Margin | E2: Rec. Price | F2: Final Price
A3: MN01 | B3: Strawberry Shortcake | C3: =E19 | D3: 0.6 | E3: =C3/(1-D3) -> 0 | F3: =E3 -> 0
A4: MN02 | B4: Double Choc Brownie | C4: =E31 | D4: 0.55 | E4: =C4/(1-D4) -> 0 | F4: =E4 -> 0
A5: MN03 | B5: Oatmeal Cookie | C5: =E43 | D5: 0.5 | E5: =C5/(1-D5) -> 0 | F5: =E5 -> 0
A6: MN04 | B6: Butter Croissant | C6: =E55 | D6: 0.5 | E6: =C6/(1-D6) -> 0 | F6: =E6 -> 0
A7: MN05 | B7: Coconut Pie | C7: =E67 | D7: 0.6 | E7: =C7/(1-D7) -> 0 | F7: =E7 -> 0
A11: RECIPE: Strawberry Shortcake
A12: Ing | B12: Qty(g) | C12: Cost/g | D12: Line Cost
C13: =IFERROR(VLOOKUP(A13,'1_Inventory'!$B$3:$G$20,6,FALSE),0) -> 0 | D13: =B13*C13 -> 0
C14: =IFERROR(VLOOKUP(A14,'1_Inventory'!$B$3:$G$20,6,FALSE),0) -> 0 | D14: =B14*C14 -> 0
C15: =IFERROR(VLOOKUP(A15,'1_Inventory'!$B$3:$G$20,6,FALSE),0) -> 0 | D15: =B15*C15 -> 0
C16: =IFERROR(VLOOKUP(A16,'1_Inventory'!$B$3:$G$20,6,FALSE),0) -> 0 | D16: =B16*C16 -> 0
C17: =IFERROR(VLOOKUP(A17,'1_Inventory'!$B$3:$G$20,6,FALSE),0) -> 0 | D17: =B17*C17 -> 0
C18: Raw Cost | D18: =SUM(D13:D17) -> 0
C19: Total (Loss 10%) | D19: =D18/0.9 -> 0
A23: RECIPE: Double Choc Brownie
A24: Ing | B24: Qty(g) | C24: Cost/g | D24: Line Cost
C25: =IFERROR(VLOOKUP(A25,'1_Inventory'!$B$3:$G$20,6,FALSE),0) -> 0 | D25: =B25*C25 -> 0
C26: =IFERROR(VLOOKUP(A26,'1_Inventory'!$B$3:$G$20,6,FALSE),0) -> 0 | D26: =B26*C26 -> 0
C27: =IFERROR(VLOOKUP(A27,'1_Inventory'!$B$3:$G$20,6,FALSE),0) -> 0 | D27: =B27*C27 -> 0
C28: =IFERROR(VLOOKUP(A28,'1_Inventory'!$B$3:$G$20,6,FALSE),0) -> 0 | D28: =B28*C28 -> 0
C29: =IFERROR(VLOOKUP(A29,'1_Inventory'!$B$3:$G$20,6,FALSE),0) -> 0 | D29: =B29*C29 -> 0
C30: Raw Cost | D30: =SUM(D25:D29) -> 0
C31: Total (Loss 10%) | D31: =D30/0.9 -> 0
A35: RECIPE: Oatmeal Cookie
A36: Ing | B36: Qty(g) | C36: Cost/g | D36: Line Cost
C37: =IFERROR(VLOOKUP(A37,'1_Inventory'!$B$3:$G$20,6,FALSE),0) -> 0 | D37: =B37*C37 -> 0
C38: =IFERROR(VLOOKUP(A38,'1_Inventory'!$B$3:$G$20,6,FALSE),0) -> 0 | D38: =B38*C38 -> 0
C39: =IFERROR(VLOOKUP(A39,'1_Inventory'!$B$3:$G$20,6,FALSE),0) -> 0 | D39: =B39*C39 -> 0
C40: =IFERROR(VLOOKUP(A40,'1_Inventory'!$B$3:$G$20,6,FALSE),0) -> 0 | D40: =B40*C40 -> 0
C41: =IFERROR(VLOOKUP(A41,'1_Inventory'!$B$3:$G$20,6,FALSE),0) -> 0 | D41: =B41*C41 -> 0
C42: Raw Cost | D42: =SUM(D37:D41) -> 0
C43: Total (Loss 10%) | D43: =D42/0.9 -> 0
A47: RECIPE: Butter Croissant
A48: Ing | B48: Qty(g) | C48: Cost/g | D48: Line Cost
C49: =IFERROR(VLOOKUP(A49,'1_Inventory'!$B$3:$G$20,6,FALSE),0) -> 0 | D49: =B49*C49 -> 0
C50: =IFERROR(VLOOKUP(A50,'1_Inventory'!$B$3:$G$20,6,FALSE),0) -> 0 | D50: =B50*C50 -> 0
C51: =IFERROR(VLOOKUP(A51,'1_Inventory'!$B$3:$G$20,6,FALSE),0) -> 0 | D51: =B51*C51 -> 0
C52: =IFERROR(VLOOKUP(A52,'1_Inventory'!$B$3:$G$20,6,FALSE),0) -> 0 | D52: =B52*C52 -> 0
...

Sheet 3_Daily_Sales
A1: DAILY SALES LOG
A2: Date | B2: Item | C2: Qty | D2: Price | E2: Cost | F2: Total Sales | G2: Total Cost | H2: Profit
D3: =IFERROR(VLOOKUP(B3,'2_Recipe_Master'!$B$3:$F$7,5,FALSE),0) -> 0 | E3: =IFERROR(VLOOKUP(B3,'2_Recipe_Master'!$B$3:$F$7,2,FALSE),0) -> 0 | F3: =C3*D3 -> 0 | G3: =C3*E3 -> 0 | H3: =F3-G3 -> 0
D4: =IFERROR(VLOOKUP(B4,'2_Recipe_Master'!$B$3:$F$7,5,FALSE),0) -> 0 | E4: =IFERROR(VLOOKUP(B4,'2_Recipe_Master'!$B$3:$F$7,2,FALSE),0) -> 0 | F4: =C4*D4 -> 0 | G4: =C4*E4 -> 0 | H4: =F4-G4 -> 0
D5: =IFERROR(VLOOKUP(B5,'2_Recipe_Master'!$B$3:$F$7,5,FALSE),0) -> 0 | E5: =IFERROR(VLOOKUP(B5,'2_Recipe_Master'!$B$3:$F$7,2,FALSE),0) -> 0 | F5: =C5*D5 -> 0 | G5: =C5*E5 -> 0 | H5: =F5-G5 -> 0
D6: =IFERROR(VLOOKUP(B6,'2_Recipe_Master'!$B$3:$F$7,5,FALSE),0) -> 0 | E6: =IFERROR(VLOOKUP(B6,'2_Recipe_Master'!$B$3:$F$7,2,FALSE),0) -> 0 | F6: =C6*D6 -> 0 | G6: =C6*E6 -> 0 | H6: =F6-G6 -> 0
D7: =IFERROR(VLOOKUP(B7,'2_Recipe_Master'!$B$3:$F$7,5,FALSE),0) -> 0 | E7: =IFERROR(VLOOKUP(B7,'2_Recipe_Master'!$B$3:$F$7,2,FALSE),0) -> 0 | F7: =C7*D7 -> 0 | G7: =C7*E7 -> 0 | H7: =F7-G7 -> 0
D8: =IFERROR(VLOOKUP(B8,'2_Recipe_Master'!$B$3:$F$7,5,FALSE),0) -> 0 | E8: =IFERROR(VLOOKUP(B8,'2_Recipe_Master'!$B$3:$F$7,2,FALSE),0) -> 0 | F8: =C8*D8 -> 0 | G8: =C8*E8 -> 0 | H8: =F8-G8 -> 0
D9: =IFERROR(VLOOKUP(B9,'2_Recipe_Master'!$B$3:$F$7,5,FALSE),0) -> 0 | E9: =IFERROR(VLOOKUP(B9,'2_Recipe_Master'!$B$3:$F$7,2,FALSE),0) -> 0 | F9: =C9*D9 -> 0 | G9: =C9*E9 -> 0 | H9: =F9-G9 -> 0
D10: =IFERROR(VLOOKUP(B10,'2_Recipe_Master'!$B$3:$F$7,5,FALSE),0) -> 0 | E10: =IFERROR(VLOOKUP(B10,'2_Recipe_Master'!$B$3:$F$7,2,FALSE),0) -> 0 | F10: =C10*D10 -> 0 | G10: =C10*E10 -> 0 | H10: =F10-G10 -> 0
D11: =IFERROR(VLOOKUP(B11,'2_Recipe_Master'!$B$3:$F$7,5,FALSE),0) -> 0 | E11: =IFERROR(VLOOKUP(B11,'2_Recipe_Master'!$B$3:$F$7,2,FALSE),0) -> 0 | F11: =C11*D11 -> 0 | G11: =C11*E11 -> 0 | H11: =F11-G11 -> 0
D12: =IFERROR(VLOOKUP(B12,'2_Recipe_Master'!$B$3:$F$7,5,FALSE),0) -> 0 | E12: =IFERROR(VLOOKUP(B12,'2_Recipe_Master'!$B$3:$F$7,2,FALSE),0) -> 0 | F12: =C12*D12 -> 0 | G12: =C12*E12 -> 0 | H12: =F12-G12 -> 0
D13: =IFERROR(VLOOKUP(B13,'2_Recipe_Master'!$B$3:$F$7,5,FALSE),0) -> 0 | E13: =IFERROR(VLOOKUP(B13,'2_Recipe_Master'!$B$3:$F$7,2,FALSE),0) -> 0 | F13: =C13*D13 -> 0 | G13: =C13*E13 -> 0 | H13: =F13-G13 -> 0
D14: =IFERROR(VLOOKUP(B14,'2_Recipe_Master'!$B$3:$F$7,5,FALSE),0) -> 0 | E14: =IFERROR(VLOOKUP(B14,'2_Recipe_Master'!$B$3:$F$7,2,FALSE),0) -> 0 | F14: =C14*D14 -> 0 | G14: =C14*E14 -> 0 | H14: =F14-G14 -> 0
... D52: =IFERROR(VLOOKUP(B52,'2_Recipe_Master'!$B$3:$F$7,5,FALSE),0) -> 0 | E52: =IFERROR(VLOOKUP(B52,'2_Recipe_Master'!$B$3:$F$7,2,FALSE),0) -> 0 | F52: =C52*D52 -> 0 | G52: =C52*E52 -> 0 | H52: =F52-G52 -> 0

Sheet 4_Dashboard
B1: OWNER DASHBOARD | H1: Last Update: Live
B3: Total Revenue | D3: Total Cost | F3: Net Profit | H3: Avg Margin % | K3: Menu Analysis
B4: =SUM('3_Daily_Sales'!F:F) -> 0 | D4: =SUM('3_Daily_Sales'!G:G) -> 0 | F4: =SUM('3_Daily_Sales'!H:H) -> 0 | H4: =IF(B4=0,0,F4/B4) -> 0 | K4: Menu Name | L4: Total Qty | M4: Total Sales
K5: ='2_Recipe_Master'!B3 -> Strawberry Shortcake | L5: =SUMIF('3_Daily_Sales'!B:B, K5, '3_Daily_Sales'!C:C) -> 0 | M5: =SUMIF('3_Daily_Sales'!B:B, K5, '3_Daily_Sales'!F:F) -> 0
K6: ='2_Recipe_Master'!B4 -> Double Choc Brownie | L6: =SUMIF('3_Daily_Sales'!B:B, K6, '3_Daily_Sales'!C:C) -> 0 | M6: =SUMIF('3_Daily_Sales'!B:B, K6, '3_Daily_Sales'!F:F) -> 0
K7: ='2_Recipe_Master'!B5 -> Oatmeal Cookie | L7: =SUMIF('3_Daily_Sales'!B:B, K7, '3_Daily_Sales'!C:C) -> 0 | M7: =SUMIF('3_Daily_Sales'!B:B, K7, '3_Daily_Sales'!F:F) -> 0
K8: ='2_Recipe_Master'!B6 -> Butter Croissant | L8: =SUMIF('3_Daily_Sales'!B:B, K8, '3_Daily_Sales'!C:C) -> 0 | M8: =SUMIF('3_Daily_Sales'!B:B, K8, '3_Daily_Sales'!F:F) -> 0
K9: ='2_Recipe_Master'!B7 -> Coconut Pie | L9: =SUMIF('3_Daily_Sales'!B:B, K9, '3_Daily_Sales'!C:C) -> 0 | M9: =SUMIF('3_Daily_Sales'!B:B, K9, '3_Daily_Sales'!F:F) -> 0
